<?xml version="1.0" encoding="utf-8"?>
<robot name="sole_biped">
    <material name="black">
        <color rgba="0.0 0.0 0.0 1.0"/>
    </material>
    <material name="blue">
        <color rgba="0.0 0.0 0.8 1.0"/>
    </material>
    <material name="green">
        <color rgba="0.0 0.8 0.0 1.0"/>
    </material>
    <material name="grey">
        <color rgba="0.2 0.2 0.2 1.0"/>
    </material>
    <material name="silver">
        <color rgba="0.9137254901960784 0.9137254901960784 0.8470588235294118 1.0"/>
    </material>
    <material name="orange">
        <color rgba="1.0 0.4235294117647059 0.0392156862745098 1.0"/>
    </material>
    <material name="brown">
        <color rgba="0.8705882352941177 0.8117647058823529 0.7647058823529411 1.0"/>
    </material>
    <material name="red">
        <color rgba="0.8 0.0 0.0 1.0"/>
    </material>
    <material name="white">
        <color rgba="1.0 1.0 1.0 1.0"/>
    </material>
    <!-- ros_control plugin -->
    <link
            name="base_Link">
        <inertial>
            <origin rpy="0 0 0" xyz="0.01233 0.00075 -0.00619"/>
            <mass value="9.563"/>
            <!-- <inertia ixx="114072.37E-06" ixy="358.31E-06" ixz="24740.39E-06"
                     iyy="93069.48E-06" iyz="-519.61E-06" izz="84503.56E-06"/> -->
            <inertia ixx="136590.556E-06" ixy="-112.830E-06" ixz="29836.42E-06"
                     iyy="111139.956E-06" iyz="175.735E-06" izz="98152.136E-06"/>
        </inertial>
        <visual>
            <origin
                    xyz="0 0 0"
                    rpy="0 0 0"/>
            <geometry>
                <mesh
                        filename="../meshes/base_Link.STL"/>
            </geometry>
            <material
                    name="">
                <color
                        rgba="0.79216 0.81961 0.93333 1"/>
            </material>
        </visual>
        <collision>
            <origin xyz="-0.005 0 0.08969" rpy="0 0 0"/>
            <geometry>
                <box size="0.28 0.24 0.20"/>
            </geometry>
        </collision>
    </link>
    <joint name="limx_imu_joint" type="fixed">
        <origin rpy="0. 0. 0." xyz="0. 0. 0."/>
        <parent link="base_Link"/>
        <child link="limx_imu"/>
    </joint>
    <!-- Imu link -->
    <link name="limx_imu">
        <inertial>
            <mass value="0.01"/>
            <origin rpy="0 0 0" xyz="0 0 0"/>
            <inertia ixx="0.000001" ixy="0" ixz="0" iyy="0.000001" iyz="0" izz="0.000001"/>
        </inertial>
        <visual>
            <origin rpy="0 0 0" xyz="0 0 0"/>
            <geometry>
                <box size="0.015 0.015 0.004"/>
            </geometry>
        </visual>
        <material name="orange">
            <color rgba="255 108 10 255"/>
        </material>
    </link>
    <gazebo reference="limx_imu">
        <material>Gazebo/Orange</material>
    </gazebo>
    <gazebo reference="limx_imu_joint">
        <disableFixedJointLumping>true</disableFixedJointLumping>
    </gazebo>
    <link
            name="abad_L_Link">
        <inertial>
            <origin rpy="0 0 0" xyz="-67.676E-03 44.613E-03 0.863E-03"/>
            <mass value="1.556"/>
            <!-- <inertia ixx="1656.04E-06" ixy="403.19E-06" ixz="-9.83E-06"
                     iyy="2566.66E-06" iyz="-15.3E-06" izz="2283.42E-06"/> -->
            <inertia ixx="1621.843E-06" ixy="402.1E-06" ixz="-22.295E-06"
                     iyy="2577.378E-06" iyz="-6.003E-06" izz="2240.059E-06"/>
        </inertial>
        <visual>
            <origin
                    xyz="0 0 0"
                    rpy="0 0 0"/>
            <geometry>
                <mesh
                        filename="../meshes/abad_L_Link.STL"/>
            </geometry>
            <material
                    name="">
                <color
                        rgba="0.79216 0.81961 0.93333 1"/>
            </material>
        </visual>
        <collision>
            <origin xyz="-0.08 0 0" rpy="1.57 0 0"/>
            <geometry>
                <cylinder length="0.05" radius="0.05"/>
            </geometry>
        </collision>
    </link>
    <joint
            name="abad_L_Joint"
            type="revolute">
        <origin
                xyz="39E-03 109.5E-03 -87.25E-03"
                rpy="0 0 0"/>
        <parent
                link="base_Link"/>
        <child
                link="abad_L_Link"/>
        <axis
                xyz="1 0 0"/>
        <limit effort="80.0" lower="-0.38397" upper="1.39626" velocity="15.0"/>
    </joint>
    <link
            name="hip_L_Link">
        <inertial>
            <origin rpy="0 0 0" xyz="-28.906E-03 -47.522E-03 -40.716E-03"/>
            <mass value="2.330"/>
            <inertia ixx="17854.401E-06" ixy="1686.919E-06" ixz="-9799.243E-06"
                     iyy="24186.469E-06" iyz="2257.438E-06" izz="9807.208E-06"/>
        </inertial>
        <visual>
            <origin
                    xyz="0 0 0"
                    rpy="0 0 0"/>
            <geometry>
                <mesh
                        filename="../meshes/hip_L_Link.STL"/>
            </geometry>
            <material
                    name="">
                <color
                        rgba="1 1 1 1"/>
            </material>
        </visual>
        <collision>
            <origin xyz="-0.10 -0.025 -0.14" rpy="0 0.53 0"/>
            <geometry>
                <cylinder length="0.15" radius="0.025"/>
            </geometry>
        </collision>
    </link>
    <joint
            name="hip_L_Joint"
            type="revolute">
        <origin
                xyz="-77E-03 20.5E-03 0"
                rpy="0 0 0"/>
        <parent
                link="abad_L_Link"/>
        <child
                link="hip_L_Link"/>
        <axis
                xyz="0 1 0"/>
        <limit effort="80.0" lower="-1.012291" upper="1.396263" velocity="15.0"/>
    </joint>
    <link
            name="knee_L_Link">
        <inertial>
            <origin rpy="0 0 0" xyz="100.966E-03 2.245E-03 -169.973E-03"/>
            <mass value="1.067"/>
            <inertia ixx="11386.716E-06" ixy="-44.269E-06" ixz="6311.427E-06"
                     iyy="15031.136E-06" iyz="77.469E-06" izz="4168.62E-06"/>
        </inertial>
        <visual>
            <origin
                    xyz="0 0 0"
                    rpy="0 0 0"/>
            <geometry>
                <mesh
                        filename="../meshes/knee_L_Link.STL"/>
            </geometry>
            <material
                    name="">
                <color
                        rgba="0.79216 0.81961 0.93333 1"/>
            </material>
        </visual>
        <collision>
            <origin xyz="0.078 0 -0.12" rpy="0 -0.55 0"/>
            <geometry>
                <cylinder length="0.26" radius="0.015"/>
            </geometry>
        </collision>
    </link>
    <joint
            name="knee_L_Joint"
            type="revolute">
        <origin
                xyz="-150E-03 -20.5E-03 -259.81E-03"
                rpy="0 0 0"/>
        <parent
                link="hip_L_Link"/>
        <child
                link="knee_L_Link"/>
        <axis
                xyz="0 -1 0"/>
        <limit effort="80" lower="-0.872665" upper="1.361357" velocity="15"/>
    </joint>
    <link
            name="ankle_L_Link">
        <inertial>
            <origin rpy="0 0 0" xyz="-18.44E-03 0.56E-03 -30.99E-03"/>
            <mass value="0.608" />
            <inertia ixx="518.19E-06" ixy="24.822E-06" ixz="63.190E-06"
                iyy="1736.063E-06" iyz="-14.547E-06" izz="1940.783E-06" />
        </inertial>
        <visual>
            <origin
                    xyz="0 0 0"
                    rpy="0 0 0"/>
            <geometry>
                <mesh
                        filename="../meshes/L_foot.STL"/>
            </geometry>
            <material
                    name="">
                <color
                        rgba="0.26667 0.26667 0.26667 1"/>
            </material>
        </visual>
        <collision>
            <origin
                    xyz="0 0 0"
                    rpy="0 0 0"/>
            <geometry>
                <mesh
                        filename="../meshes/L_foot.STL"/>
            </geometry>
            <material
                    name="">
                <color
                        rgba="0.26667 0.26667 0.26667 1"/>
            </material>
        </collision>
    </link>
    <joint
            name="ankle_L_Joint"
            type="revolute">
        <origin
                xyz="156E-03 0 -259.81E-03"
                rpy="0 0 0"/>
        <parent
                link="knee_L_Link"/>
        <child
                link="ankle_L_Link"/>
        <axis
                xyz="0 -1 0"/>

        <limit effort="20" lower="-1.11352" upper="1.11352" velocity="10"/>
    </joint>
    
    <link
            name="abad_R_Link">
        <inertial>
            <origin rpy="0 0 0" xyz="-67.676E-03 -44.613E-03 0.863E-03"/>
            <mass value="1.556"/>
            <!-- <inertia ixx="1656.04E-06" ixy="-403.19E-06" ixz="-9.83E-06"
                     iyy="2566.66E-06" iyz="15.3E-06" izz="2283.42E-06"/> -->
            <inertia ixx="1621.843E-06" ixy="-402.1E-06" ixz="-22.295E-06"
                     iyy="2577.378E-06" iyz="6.003E-06" izz="2240.059E-06"/>
        </inertial>
        <visual>
            <origin
                    xyz="0 0 0"
                    rpy="0 0 0"/>
            <geometry>
                <mesh
                        filename="../meshes/abad_R_Link.STL"/>
            </geometry>
            <material
                    name="">
                <color
                        rgba="0.79216 0.81961 0.93333 1"/>
            </material>
        </visual>
        <collision>
            <origin xyz="-0.08 0 0" rpy="1.57 0 0"/>
            <geometry>
                <cylinder length="0.05" radius="0.05"/>
            </geometry>
        </collision>
    </link>
    <joint
            name="abad_R_Joint"
            type="revolute">
        <origin
                xyz="39E-03 -109.5E-03 -87.25E-03"
                rpy="0 0 0"/>
        <parent
                link="base_Link"/>
        <child
                link="abad_R_Link"/>
        <axis
                xyz="1 0 0"/>
        <limit effort="80.0" lower="-1.39626" upper="0.38397" velocity="15.0"/>
    </joint>
    <link
            name="hip_R_Link">
        <inertial>
            <origin rpy="0 0 0" xyz="-28.906E-03 47.522E-03 -40.716E-03"/>
            <mass value="2.330"/>
            <inertia ixx="17854.401E-06" ixy="-1686.919E-06" ixz="-9799.243E-06"
                    iyy="24186.469E-06" iyz="-2257.438E-06" izz="9807.208E-06"/>
        </inertial>
        <visual>
            <origin
                    xyz="0 0 0"
                    rpy="0 0 0"/>
            <geometry>
                <mesh
                        filename="../meshes/hip_R_Link.STL"/>
            </geometry>
            <material
                    name="">
                <color
                        rgba="1 1 1 1"/>
            </material>
        </visual>
        <collision>
            <origin xyz="-0.10 0.025 -0.14" rpy="0 0.53 0"/>
            <geometry>
                <cylinder length="0.15" radius="0.025"/>
            </geometry>
        </collision>
    </link>
    <joint
            name="hip_R_Joint"
            type="revolute">
        <origin
                xyz="-77E-03 -20.5E-03 0"
                rpy="0 0 0"/>
        <parent
                link="abad_R_Link"/>
        <child
                link="hip_R_Link"/>
        <axis
                xyz="0 -1 0"/>
        <limit effort="80.0" lower="-1.396263" upper="1.012291" velocity="15.0"/>
    </joint>
    <link
            name="knee_R_Link">
        <inertial>
            <origin rpy="0 0 0" xyz="100.966E-03 -2.245E-03 -169.973E-03"/>
            <mass value="1.067"/>
            <inertia ixx="11386.716E-06" ixy="44.269E-06" ixz="6311.427E-06"
                    iyy="15031.136E-06" iyz="-77.469E-06" izz="4168.62E-06"/>
        </inertial>
        <visual>
            <origin
                    xyz="0 0 0"
                    rpy="0 0 0"/>
            <geometry>
                <mesh
                        filename="../meshes/knee_R_Link.STL"/>
            </geometry>
            <material
                    name="">
                <color
                        rgba="0.79216 0.81961 0.93333 1"/>
            </material>
        </visual>
        <collision>
            <origin xyz="0.078 0 -0.12" rpy="0 -0.55 0"/>
            <geometry>
                <cylinder length="0.26" radius="0.015"/>
            </geometry>
        </collision>
    </link>
    <joint
            name="knee_R_Joint"
            type="revolute">
        <origin
                xyz="-150E-03 20.5E-03 -259.81E-03"
                rpy="0 0 0"/>
        <parent
                link="hip_R_Link"/>
        <child
                link="knee_R_Link"/>
        <axis
                xyz="0 1 0"/>
        <limit effort="80" lower="-1.361357" upper="0.872665" velocity="15"/>
    </joint>
    <link
            name="ankle_R_Link">
        <inertial>
            <origin rpy="0 0 0" xyz="-18.44E-03 0.56E-03 -30.99E-03"/>
            <mass value="0.608" />
             <inertia ixx="518.19E-06" ixy="-24.822E-06" ixz="63.190E-06"
                    iyy="1736.063E-06" iyz="14.547E-06" izz="1940.783E-06" />
        </inertial>
        <visual>
            <origin
                    xyz="0 0 0"
                    rpy="0 0 0"/>
            <geometry>
                <mesh
                        filename="../meshes/R_foot.STL"/>
            </geometry>
            <material
                    name="">
                <color
                        rgba="0.26667 0.26667 0.26667 1"/>
            </material>
        </visual>
        <collision>
            <origin
                    xyz="0 0 0"
                    rpy="0 0 0"/>
            <geometry>
                <mesh
                        filename="../meshes/R_foot.STL"/>
            </geometry>
            <material
                    name="">
                <color
                        rgba="0.26667 0.26667 0.26667 1"/>
            </material>
        </collision>
    </link>
    <joint
            name="ankle_R_Joint"
            type="revolute">
        <origin
                xyz="156E-03 0 -259.81E-03"
                rpy="0 0 0"/>
        <parent
                link="knee_R_Link"/>
        <child
                link="ankle_R_Link"/>
        <axis
                xyz="0 -1 0"/>

        <limit effort="20" lower="-1.11352" upper="1.11352" velocity="10"/>
    </joint>
</robot>